Workbook

Sheet TABELA SPOLINE
A1: ID | B1: DESCRIÇÃO | C1: LAMPADA | D1: WATTS | E1: LUMENS | F1: ALTURA | G1: LARGURA | H1: COMPRIMENTO | I1: CABO | J1: PREÇO | K1: OBS.
A2: 84 | B2: 385/2 PLAFON SMART BRANCO | C2: 2 x E27 | D2: - | E2: - | F2: 95MM | G2: 250MM | H2: 250MM | I2: - | J2: 84.588 | L2: =VLOOKUP(A2,Formulas!A:B,2,FALSE) -> 092032
A3: 85 | B3: 385/2 PLAFON SMART CAFÉ | C3: 2 x E27 | D3: - | E3: - | F3: 95MM | G3: 250MM | H3: 250MM | I3: - | J3: 84.588 | L3: =VLOOKUP(A3,Formulas!A:B,2,FALSE) -> 092033
A4: 86 | B4: 385/2 PLAFON SMART COBRE POLIDO | C4: 2 x E27 | D4: - | E4: - | F4: 95MM | G4: 250MM | H4: 250MM | I4: - | J4: 101.5056 | L4: =VLOOKUP(A4,Formulas!A:B,2,FALSE) -> 092034
A5: 90 | B5: 385/2 PLAFON SMART PRETO | C5: 2 x E27 | D5: - | E5: - | F5: 95MM | G5: 250MM | H5: 250MM | I5: - | J5: 84.588 | L5: =VLOOKUP(A5,Formulas!A:B,2,FALSE) -> 092036
A6: 97 | B6: 385/3 PLAFON SMART BRANCO | C6: 3 x E27 | D6: - | E6: - | F6: 95MM | G6: 350MM | H6: 350MM | I6: - | J6: 139.125 | L6: =VLOOKUP(A6,Formulas!A:B,2,FALSE) -> 092040
A7: 98 | B7: 385/3 PLAFON SMART CAFÉ | C7: 3 x E27 | D7: - | E7: - | F7: 95MM | G7: 350MM | H7: 350MM | I7: - | J7: 139.125 | L7: =VLOOKUP(A7,Formulas!A:B,2,FALSE) -> 092041
A8: 99 | B8: 385/3 PLAFON SMART COBRE POLIDO | C8: 3 x E27 | D8: - | E8: - | F8: 95MM | G8: 350MM | H8: 350MM | I8: - | J8: 166.95 | L8: =VLOOKUP(A8,Formulas!A:B,2,FALSE) -> 092042
A9: 103 | B9: 385/3 PLAFON SMART PRETO | C9: 3 x E27 | D9: - | E9: - | F9: 95MM | G9: 350MM | H9: 350MM | I9: - | J9: 139.125 | L9: =VLOOKUP(A9,Formulas!A:B,2,FALSE) -> 092044
A10: 110 | B10: 385/5 PLAFON SMART BRANCO | C10: 5 x E27 | D10: - | E10: - | F10: 95MM | G10: 550MM | H10: 550MM | I10: - | J10: 267.12 | L10: =VLOOKUP(A10,Formulas!A:B,2,FALSE) -> 092048
A11: 111 | B11: 385/5 PLAFON SMART CAFÉ | C11: 5 x E27 | D11: - | E11: - | F11: 95MM | G11: 550MM | H11: 550MM | I11: - | J11: 267.12 | L11: =VLOOKUP(A11,Formulas!A:B,2,FALSE) -> 092049
A12: 112 | B12: 385/5 PLAFON SMART COBRE POLIDO | C12: 5 x E27 | D12: - | E12: - | F12: 95MM | G12: 550MM | H12: 550MM | I12: - | J12: 320.544 | L12: =VLOOKUP(A12,Formulas!A:B,2,FALSE) -> 092050
A13: 116 | B13: 385/5 PLAFON SMART PRETO | C13: 5 x E27 | D13: - | E13: - | F13: 95MM | G13: 550MM | H13: 550MM | I13: - | J13: 267.12 | L13: =VLOOKUP(A13,Formulas!A:B,2,FALSE) -> 092052
... A61: 871 | B61: 733/6 PENDENTE CENTURY PRETO | C61: 6 X E27 | D61: - | E61: - | F61: 360MM | G61: 150MM | H61: 1200MM | I61: 1500MM | J61: 578.76 | L61: =VLOOKUP(A61,Formulas!A:B,2,FALSE) -> 092298
A62: 873 | B62: 735/25 PLAFON NEW SMART BRANCO3000K | C62: LED BIVOLT | D62: 18WATTS | E62: 1350 | F62: 50MM | G62: 250MM | H62: 250MM | I62: - | J62: 131.334 | L62: =VLOOKUP(A62,Formulas!A:B,2,FALSE) -> 092056
A63: 879 | B63: 735/25 PLAFON NEW SMART PRETO3000K | C63: LED BIVOLT | D63: 18WATTS | E63: 1350 | F63: 50MM | G63: 250MM | H63: 250MM | I63: - | J63: 131.334 | L63: =VLOOKUP(A63,Formulas!A:B,2,FALSE) -> 092058
A64: 882 | B64: 735/35 PLAFON NEW SMART BRANCO3000K | C64: LED BIVOLT | D64: 36WATTS | E64: 2700 | F64: 50MM | G64: 350MM | H64: 350MM | I64: - | J64: 171.402 | L64: =VLOOKUP(A64,Formulas!A:B,2,FALSE) -> 092066
A65: 891 | B65: 735/35 PLAFON NEW SMART PRETO3000K | C65: LED BIVOLT | D65: 36WATTS | E65: 2700 | F65: 50MM | G65: 350MM | H65: 350MM | I65: - | J65: 171.402 | L65: =VLOOKUP(A65,Formulas!A:B,2,FALSE) -> 092069
A66: 894 | B66: 735/50 PLAFON NEW SMART BRANCO3000K | C66: LED BIVOLT | D66: 50WATTS | E66: 3750 | F66: 50MM | G66: 500MM | H66: 500MM | I66: - | J66: 389.55 | L66: =VLOOKUP(A66,Formulas!A:B,2,FALSE) -> 092076
A67: 901 | B67: 735/50 PLAFON NEW SMART PRETO3000K | C67: LED BIVOLT | D67: 50WATTS | E67: 3750 | F67: 50MM | G67: 500MM | H67: 500MM | I67: - | J67: 389.55 | L67: =VLOOKUP(A67,Formulas!A:B,2,FALSE) -> 092078
A68: 965 | B68: 757/1 ARANDELA DROP BRANCO | C68: 1 X G9 | D68: - | E68: - | F68: 220MM | G68: 120MM | H68: 160MM | I68: - | J68: 107.961 | L68: =VLOOKUP(A68,Formulas!A:B,2,FALSE) -> 092691
A69: 968 | B69: 757/1 ARANDELA DROP DOURADO ONO | C69: 1 X G9 | D69: - | E69: - | F69: 220MM | G69: 120MM | H69: 160MM | I69: - | J69: 107.961 | L69: =VLOOKUP(A69,Formulas!A:B,2,FALSE) -> 092694
A70: 969 | B70: 757/1 ARANDELA DROP PRETO | C70: 1 X G9 | D70: - | E70: - | F70: 220MM | G70: 120MM | H70: 160MM | I70: - | J70: 107.961 | L70: =VLOOKUP(A70,Formulas!A:B,2,FALSE) -> 092695
A71: 971 | B71: 757/1 ARANDELA DROP DOURADO POLIDO | C71: 1 X G9 | D71: - | E71: - | F71: 220MM | G71: 120MM | H71: 160MM | I71: - | J71: 129.5532 | L71: =VLOOKUP(A71,Formulas!A:B,2,FALSE) -> 092696
A72: 984 | B72: 765/1 LUMINARIA DE MESA DROP BRANCO | C72: 1 X G9 | D72: - | E72: - | F72: 300MM | G72: 130MM | H72: 170MM | I72: - | J72: 144.69 | L72: =VLOOKUP(A72,Formulas!A:B,2,FALSE) -> 092901
A73: 985 | B73: 765/1 LUMINARIA DE MESA DROP COBRE POLIDO | C73: 1 X G9 | D73: - | E73: - | F73: 300MM | G73: 130MM | H73: 170MM | I73: - | J73: 173.628 | L73: =VLOOKUP(A73,Formulas!A:B,2,FALSE) -> 092902
A74: 986 | B74: 765/1 LUMINARIA DE MESA DROP DOURADO ONO | C74: 1 X G9 | D74: - | E74: - | F74: 300MM | G74: 130MM | H74: 170MM | I74: - | J74: 144.69 | L74: =VLOOKUP(A74,Formulas!A:B,2,FALSE) -> 092903
A75: 987 | B75: 765/1 LUMINARIA DE MESA DROP DOURADO POLIDO | C75: 1 X G9 | D75: - | E75: - | F75: 300MM | G75: 130MM | H75: 170MM | I75: - | J75: 173.628 | L75: =VLOOKUP(A75,Formulas!A:B,2,FALSE) -> 092904
A76: 988 | B76: 765/1 LUMINARIA DE MESA DROP PRETO | C76: 1 X G9 | D76: - | E76: - | F76: 300MM | G76: 130MM | H76: 170MM | I76: - | J76: 144.69 | L76: =VLOOKUP(A76,Formulas!A:B,2,FALSE) -> 092905
A77: 997 | B77: 777/1 ARANDELA PENDULO BRANCO VIDRO LEITOSO | C77: 1 X G9 | D77: - | E77: - | F77: 450MM | G77: 120MM | H77: 180MM | I77: - | J77: 148.029 | L77: =VLOOKUP(A77,Formulas!A:B,2,FALSE) -> 092705
A78: 1001 | B78: 777/1 ARANDELA PENDULO DOURADO ONO VIDRO LEITOSO | C78: 1 X G9 | D78: - | E78: - | F78: 450MM | G78: 120MM | H78: 180MM | I78: - | J78: 148.029 | L78: =VLOOKUP(A78,Formulas!A:B,2,FALSE) -> 092708
A79: 1002 | B79: 777/1 ARANDELA PENDULO DOURADO POLIDO VIDRO LEITOSO | C79: 1 X G9 | D79: - | E79: - | F79: 450MM | G79: 120MM | H79: 180MM | I79: - | J79: 177.6348 | L79: =VLOOKUP(A79,Formulas!A:B,2,FALSE) -> 092709
... A160: 1323 | B160: 808/5 PENDENTE GRAU PRETO / DOURADO POLIDO | C160: 4 X MR11 - 1 X G9 | D160: - | E160: - | F160: 140MM | G160: 120MM | H160: 1400MM | I160: 1200MM | J160: 686.721 | L160: =VLOOKUP(A160,Formulas!A:B,2,FALSE) -> #N/A
A161: 1332 | B161: 810/120 PENDENTE HALL BRANCO3000K | C161: LED BIVOLT | D161: 38WATTS | E161: 2850 | F161: 40MM | G161: 50MM | H161: 1200MM | I161: 1500MM | J161: 366.177 | L161: =VLOOKUP(A161,Formulas!A:B,2,FALSE) -> 092561
A162: 1333 | B162: 810/120 PENDENTE HALL PRETO3000K | C162: LED BIVOLT | D162: 38WATTS | E162: 2850 | F162: 40MM | G162: 50MM | H162: 1200MM | I162: 1500MM | J162: 366.177 | L162: =VLOOKUP(A162,Formulas!A:B,2,FALSE) -> 092562
A163: 1334 | B163: 810/120 PENDENTE HALL PRETO4000K | C163: LED BIVOLT | D163: 38WATTS | E163: 2850 | F163: 40MM | G163: 50MM | H163: 1200MM | I163: 1500MM | J163: 366.177 | L163: =VLOOKUP(A163,Formulas!A:B,2,FALSE) -> 092566
A164: 1340 | B164: 811/120 PENDENTE OFFICE BRANCO 3000K | C164: LED BIVOLT | D164: 18WATTS | E164: 1350 | F164: 40MM | G164: 50MM | H164: 1200mm | I164: 1500MM | J164: 263.781 | L164: =VLOOKUP(A164,Formulas!A:B,2,FALSE) -> 092577
A165: 1341 | B165: 811/120 PENDENTE OFFICE BRANCO 4000K | C165: LED BIVOLT | D165: 18WATTS | E165: 1350 | F165: 40MM | G165: 50MM | H165: 1200MM | I165: 1500MM | J165: 263.781 | L165: =VLOOKUP(A165,Formulas!A:B,2,FALSE) -> 092585
A166: 1343 | B166: 811/120 PENDENTE OFFICE BRANCO / DOURADO ESCOVADO 4000K | C166: LED BIVOLT | D166: 18WATTS | E166: 1350 | F166: 40MM | G166: 50MM | H166: 1200MM | I166: 1500MM | J166: 263.781 | L166: =VLOOKUP(A166,Formulas!A:B,2,FALSE) -> 092587
A167: 1344 | B167: 811/120 PENDENTE OFFICE PRETO 3000K | C167: LED BIVOLT | D167: 18WATTS | E167: 1350 | F167: 40MM | G167: 50MM | H167: 1200MM | I167: 1500MM | J167: 263.781 | L167: =VLOOKUP(A167,Formulas!A:B,2,FALSE) -> 092578
...

Sheet Formulas
A1: # Referência | B1: SKU | J1: # Referência | L1: Nome | M1: Id do Fabricante | N1: Fabricante | O1: Preço | P1: Preço Mínimo
A2: 44 | B2: 177938 | C2: =VLOOKUP(A2,'TABELA SPOLINE'!A:J,10,FALSE) -> #N/A | J2: 44 | K2: =TRIM(A2) -> 44 | L2: SPOT FLEX PTO TRILHO 2 x E27 300MM | M2: 7629 | N2: Spot Line Industria E Comercio | O2: 519,75 | P2: 311,97
A3: 84 | B3: 092032 | C3: =VLOOKUP(A3,'TABELA SPOLINE'!A:J,10,FALSE) -> 84.588 | D3: =C3*0.1+C3 -> 93.0468 | E3: =ROUNDUP(D3,2) -> 93.05 | F3: =E3*0.0975+E3 -> 102.12238 | G3: =ROUNDUP(F3,2) -> 102.13 | H3: 385 | I3: 2 | J3: 84-385-2 | K3: =TRIM(A3) -> 84 | L3: SPOT FLEX PTO / COBRE POL TRILHO 2 x E27 300MM | M3: 7629 | N3: Spot Line Industria E Comercio | O3: 353,45 | P3: 212,15
A4: 85 | B4: 092033 | C4: =VLOOKUP(A4,'TABELA SPOLINE'!A:J,10,FALSE) -> 84.588 | D4: =C4*0.1+C4 -> 93.0468 | E4: =ROUNDUP(D4,2) -> 93.05 | F4: =E4*0.0975+E4 -> 102.12238 | G4: =ROUNDUP(F4,2) -> 102.13 | H4: 385 | I4: 2 | J4: 85-385-2 | K4: =TRIM(A4) -> 85 | L4: SPOT FLEX BCO / COBRE POL TRILHO 2 x E27 300MM | M4: 7629 | N4: Spot Line Industria E Comercio | O4: 353,45 | P4: 212,15
A5: 86 | B5: 092034 | C5: =VLOOKUP(A5,'TABELA SPOLINE'!A:J,10,FALSE) -> 101.5056 | D5: =C5*0.1+C5 -> 111.65616 | E5: =ROUNDUP(D5,2) -> 111.66 | F5: =E5*0.0975+E5 -> 122.54685 | G5: =ROUNDUP(F5,2) -> 122.55 | H5: 385 | I5: 2 | J5: 86-385-2 | K5: =TRIM(A5) -> 86 | L5: SPOT FLEX PTO / COBRE POL BASE 2 x E27 300MM | M5: 7629 | N5: Spot Line Industria E Comercio | O5: 353,45 | P5: 212,15
A6: 88 | B6: 092035 | C6: =VLOOKUP(A6,'TABELA SPOLINE'!A:J,10,FALSE) -> #N/A | H6: 385 | I6: 2 | J6: 88-385-2 | K6: =TRIM(A6) -> 88 | L6: SPOT FLEX BCO / COBRE POL BASE 2 x E27 300MM | M6: 7629 | N6: Spot Line Industria E Comercio | O6: 353,45 | P6: 212,15
A7: 90 | B7: 092036 | C7: =VLOOKUP(A7,'TABELA SPOLINE'!A:J,10,FALSE) -> 84.588 | D7: =C7*0.1+C7 -> 93.0468 | E7: =ROUNDUP(D7,2) -> 93.05 | F7: =E7*0.0975+E7 -> 102.12238 | G7: =ROUNDUP(F7,2) -> 102.13 | H7: 385 | I7: 2 | J7: 90-385-2 | K7: =TRIM(A7) -> 90 | L7: SPOT FLEX BCO TRILHO 3 x E27 500MM | M7: 7629 | N7: Spot Line Industria E Comercio | O7: 404,25 | P7: 242,65
A8: 97 | B8: 092040 | C8: =VLOOKUP(A8,'TABELA SPOLINE'!A:J,10,FALSE) -> 139.125 | D8: =C8*0.1+C8 -> 153.0375 | E8: =ROUNDUP(D8,2) -> 153.04 | F8: =E8*0.0975+E8 -> 167.9614 | G8: =ROUNDUP(F8,2) -> 167.97 | H8: 385 | I8: 3 | J8: 97-385-3 | K8: =TRIM(A8) -> 97 | L8: SPOT FLEX BCO / COBRE LIX TRILHO 3 x E27 500MM | M8: 7629 | N8: Spot Line Industria E Comercio | O8: 485,10 | P8: 291,18
A9: 98 | B9: 092041 | C9: =VLOOKUP(A9,'TABELA SPOLINE'!A:J,10,FALSE) -> 139.125 | D9: =C9*0.1+C9 -> 153.0375 | E9: =ROUNDUP(D9,2) -> 153.04 | F9: =E9*0.0975+E9 -> 167.9614 | G9: =ROUNDUP(F9,2) -> 167.97 | H9: 385 | I9: 3 | J9: 98-385-3 | K9: =TRIM(A9) -> 98 | L9: SPOT FLEX BCO / DOU POL TRILHO 3 x E27 500MM | M9: 7629 | N9: Spot Line Industria E Comercio | O9: 485,10 | P9: 291,18
A10: 99 | B10: 092042 | C10: =VLOOKUP(A10,'TABELA SPOLINE'!A:J,10,FALSE) -> 166.95 | D10: =C10*0.1+C10 -> 183.645 | E10: =ROUNDUP(D10,2) -> 183.65 | F10: =E10*0.0975+E10 -> 201.55587 | G10: =ROUNDUP(F10,2) -> 201.56 | H10: 385 | I10: 3 | J10: 99-385-3 | K10: =TRIM(A10) -> 99 | L10: SPOT FLEX PTO TRILHO 3 x E27 500MM | M10: 7629 | N10: Spot Line Industria E Comercio | O10: 404,25 | P10: 242,65
A11: 101 | B11: 092043 | C11: =VLOOKUP(A11,'TABELA SPOLINE'!A:J,10,FALSE) -> #N/A | H11: 385 | I11: 3 | J11: 101-385-3 | K11: =TRIM(A11) -> 101 | L11: SPOT FLEX PTO | M11: 7629 | N11: Spot Line Industria E Comercio | O11: 485,10 | P11: 291,18
A12: 103 | B12: 092044 | C12: =VLOOKUP(A12,'TABELA SPOLINE'!A:J,10,FALSE) -> 139.125 | D12: =C12*0.1+C12 -> 153.0375 | E12: =ROUNDUP(D12,2) -> 153.04 | F12: =E12*0.0975+E12 -> 167.9614 | G12: =ROUNDUP(F12,2) -> 167.97 | H12: 385 | I12: 3 | J12: 103-385-3 | K12: =TRIM(A12) -> 103 | L12: SPOT FLEX PTO | M12: 7629 | N12: Spot Line Industria E Comercio | O12: 485,10 | P12: 291,18
A13: 110 | B13: 092048 | C13: =VLOOKUP(A13,'TABELA SPOLINE'!A:J,10,FALSE) -> 267.12 | D13: =C13*0.1+C13 -> 293.832 | E13: =ROUNDUP(D13,2) -> 293.84 | F13: =E13*0.0975+E13 -> 322.4894 | G13: =ROUNDUP(F13,2) -> 322.49 | H13: 385 | I13: 5 | J13: 110-385-5 | K13: =TRIM(A13) -> 110 | L13: SPOT FLEX BCO | M13: 7629 | N13: Spot Line Industria E Comercio | O13: 485,10 | P13: 291,18
A14: 111 | B14: 092049 | C14: =VLOOKUP(A14,'TABELA SPOLINE'!A:J,10,FALSE) -> 267.12 | D14: =C14*0.1+C14 -> 293.832 | E14: =ROUNDUP(D14,2) -> 293.84 | F14: =E14*0.0975+E14 -> 322.4894 | G14: =ROUNDUP(F14,2) -> 322.49 | H14: 385 | I14: 5 | J14: 111-385-5 | K14: =TRIM(A14) -> 111 | L14: SPOT TROIA PTO | M14: 7629 | N14: Spot Line Industria E Comercio | O14: 353,50 | P14: 212,18
A15: 112 | B15: 092050 | C15: =VLOOKUP(A15,'TABELA SPOLINE'!A:J,10,FALSE) -> 320.544 | D15: =C15*0.1+C15 -> 352.5984 | E15: =ROUNDUP(D15,2) -> 352.6 | F15: =E15*0.0975+E15 -> 386.9785 | G15: =ROUNDUP(F15,2) -> 386.98 | H15: 385 | I15: 5 | J15: 112-385-5 | K15: =TRIM(A15) -> 112 | L15: SPOT TROIA PTO 1 x E27 120MM 120MM | M15: 7629 | N15: Spot Line Industria E Comercio | O15: 170,38 | P15: 102,27
A16: 116 | B16: 092052 | C16: =VLOOKUP(A16,'TABELA SPOLINE'!A:J,10,FALSE) -> 267.12 | D16: =C16*0.1+C16 -> 293.832 | E16: =ROUNDUP(D16,2) -> 293.84 | F16: =E16*0.0975+E16 -> 322.4894 | G16: =ROUNDUP(F16,2) -> 322.49 | H16: 385 | I16: 5 | J16: 116-385-5 | K16: =TRIM(A16) -> 116 | L16: SPOT TROIA BCO BRILHANTE | M16: 7629 | N16: Spot Line Industria E Comercio | O16: 1 056,62 | P16: 634,23
A17: 122 | B17: 092131 | C17: =VLOOKUP(A17,'TABELA SPOLINE'!A:J,10,FALSE) -> #N/A | H17: 386 | I17: 3 | J17: 122-386-3 | K17: =TRIM(A17) -> 122 | L17: SPOT TROIA PTO TRILHO 2 x E27 300MM | M17: 7629 | N17: Spot Line Industria E Comercio | O17: 747,80 | P17: 448,86
A18: 123 | B18: 092132 | C18: =VLOOKUP(A18,'TABELA SPOLINE'!A:J,10,FALSE) -> #N/A | H18: 386 | I18: 3 | J18: 123-386-3 | K18: =TRIM(A18) -> 123 | L18: SPOT TROIA PTO | M18: 7629 | N18: Spot Line Industria E Comercio | O18: 829,35 | P18: 497,81
A19: 124 | B19: 092133 | C19: =VLOOKUP(A19,'TABELA SPOLINE'!A:J,10,FALSE) -> #N/A | H19: 386 | I19: 3 | J19: 124-386-3 | K19: =TRIM(A19) -> 124 | L19: SPOT TROIA BCO | M19: 7629 | N19: Spot Line Industria E Comercio | O19: 363,82 | P19: 218,38
A20: 126 | B20: 092134 | C20: =VLOOKUP(A20,'TABELA SPOLINE'!A:J,10,FALSE) -> #N/A | H20: 386 | I20: 3 | J20: 126-386-3 | K20: =TRIM(A20) -> 126 | L20: SPOT TROIA BCO BRILHANTE | M20: 7629 | N20: Spot Line Industria E Comercio | O20: 917,75 | P20: 550,87
A21: 126 | B21: 092136 | C21: =VLOOKUP(A21,'TABELA SPOLINE'!A:J,10,FALSE) -> #N/A | H21: 386 | I21: 3 | J21: 126-386-3 | K21: =TRIM(A21) -> 126 | L21: SPOT TROIA PTO TRILHO 3 x E27 500MM | M21: 7629 | N21: Spot Line Industria E Comercio | O21: 1 408,70 | P21: 845,56
A22: 131 | B22: 092140 | C22: =VLOOKUP(A22,'TABELA SPOLINE'!A:J,10,FALSE) -> 311.64 | D22: =C22*0.1+C22 -> 342.804 | E22: =ROUNDUP(D22,2) -> 342.81 | F22: =E22*0.0975+E22 -> 376.23397 | G22: =ROUNDUP(F22,2) -> 376.24 | H22: 386 | I22: 5 | J22: 131-386-5 | K22: =TRIM(A22) -> 131 | L22: SPOT TROIA PTO | M22: 7629 | N22: Spot Line Industria E Comercio | O22: 931,02 | P22: 558,84
A23: 132 | B23: 092141 | C23: =VLOOKUP(A23,'TABELA SPOLINE'!A:J,10,FALSE) -> #N/A | H23: 386 | I23: 5 | J23: 132-386-5 | K23: =TRIM(A23) -> 132 | L23: PLAF SMART BCO 1 x E27 95MM 250MM 250MM | M23: 7629 | N23: Spot Line Industria E Comercio | O23: 232,62 | P23: 139,63
A24: 133 | B24: 092142 | C24: =VLOOKUP(A24,'TABELA SPOLINE'!A:J,10,FALSE) -> #N/A | H24: 386 | I24: 5 | J24: 133-386-5 | K24: =TRIM(A24) -> 133 | L24: PLAF SMART CAFÉ 2 x E27 95MM 250MM 250MM | M24: 7629 | N24: Spot Line Industria E Comercio | O24: 232,62 | P24: 139,63
A25: 135 | B25: 092144 | C25: =VLOOKUP(A25,'TABELA SPOLINE'!A:J,10,FALSE) -> 311.64 | D25: =C25*0.1+C25 -> 342.804 | E25: =ROUNDUP(D25,2) -> 342.81 | F25: =E25*0.0975+E25 -> 376.23397 | G25: =ROUNDUP(F25,2) -> 376.24 | H25: 386 | I25: 5 | J25: 135-386-5 | K25: =TRIM(A25) -> 135 | L25: PLAF SMART COBRE POL 2 x E27 95MM 250MM 250MM | M25: 7629 | N25: Spot Line Industria E Comercio | O25: 279,15 | P25: 167,56
A26: 154 | B26: 177939 | C26: =VLOOKUP(A26,'TABELA SPOLINE'!A:J,10,FALSE) -> #N/A | J26: 154 | K26: =TRIM(A26) -> 154 | L26: PLAF SMART DOU POL 2 x E27 95MM 250MM 250MM | M26: 7629 | N26: Spot Line Industria E Comercio | O26: 263,35 | P26: 158,07
A27: 166 | B27: 092148 | C27: =VLOOKUP(A27,'TABELA SPOLINE'!A:J,10,FALSE) -> #N/A | H27: 415 | I27: 1 | J27: 166-415-1 | K27: =TRIM(A27) -> 166 | L27: PLAF SMART PTO 2 x E27 95MM 250MM 250MM | M27: 7629 | N27: Spot Line Industria E Comercio | O27: 232,62 | P27: 139,63
A28: 167 | B28: 092149 | C28: =VLOOKUP(A28,'TABELA SPOLINE'!A:J,10,FALSE) -> #N/A | H28: 415 | I28: 1 | J28: 167-415-1 | K28: =TRIM(A28) -> 167 | L28: PLAF SMART DOU ONO 2 x E27 95MM 250MM 250MM | M28: 7629 | N28: Spot Line Industria E Comercio | O28: 232,62 | P28: 139,63
A29: 169 | B29: 092150 | C29: =VLOOKUP(A29,'TABELA SPOLINE'!A:J,10,FALSE) -> #N/A | H29: 415 | I29: 1 | J29: 169-415-1 | K29: =TRIM(A29) -> 169 | L29: PLAF SMART COBRE ONO 2 x E27 95MM 250MM 250MM | M29: 7629 | N29: Spot Line Industria E Comercio | O29: 219,45 | P29: 131,72
A30: 170 | B30: 092151 | C30: =VLOOKUP(A30,'TABELA SPOLINE'!A:J,10,FALSE) -> #N/A | H30: 415 | I30: 1 | J30: 170-415-1 | K30: =TRIM(A30) -> 170 | L30: PLAF SMART BCO 3 x E27 95MM 350MM 350MM | M30: 7629 | N30: Spot Line Industria E Comercio | O30: 382,60 | P30: 229,65
A31: 170 | B31: 178310 | C31: =VLOOKUP(A31,'TABELA SPOLINE'!A:J,10,FALSE) -> #N/A | J31: 170 | K31: =TRIM(A31) -> 170 | L31: PLAF SMART CAFÉ 3 x E27 95MM 350MM 350MM | M31: 7629 | N31: Spot Line Industria E Comercio | O31: 382,60 | P31: 229,65
A32: 171 | B32: 178309 | C32: =VLOOKUP(A32,'TABELA SPOLINE'!A:J,10,FALSE) -> #N/A | J32: 171 | K32: =TRIM(A32) -> 171 | L32: PLAF SMART COBRE POL 3 x E27 95MM 350MM 350MM | M32: 7629 | N32: Spot Line Industria E Comercio | O32: 459,12 | P32: 275,59
A33: 172 | B33: 092152 | C33: =VLOOKUP(A33,'TABELA SPOLINE'!A:J,10,FALSE) -> #N/A | H33: 415 | I33: 1 | J33: 172-415-1 | K33: =TRIM(A33) -> 172 | L33: PLAF SMART DOU POL 3 x E27 95MM 350MM 350MM | M33: 7629 | N33: Spot Line Industria E Comercio | O33: 433,12 | P33: 259,98
A34: 172 | B34: 178307 | C34: =VLOOKUP(A34,'TABELA SPOLINE'!A:J,10,FALSE) -> #N/A | J34: 172 | K34: =TRIM(A34) -> 172 | L34: PLAF SMART PTO 3 x E27 95MM 350MM 350MM | M34: 7629 | N34: Spot Line Industria E Comercio | O34: 382,60 | P34: 229,65
A35: 173 | B35: 092153 | C35: =VLOOKUP(A35,'TABELA SPOLINE'!A:J,10,FALSE) -> #N/A | H35: 415 | I35: 1 | J35: 173-415-1 | K35: =TRIM(A35) -> 173 | L35: PLAF SMART DOU ONO 3 x E27 95MM 350MM 350MM | M35: 7629 | N35: Spot Line Industria E Comercio | O35: 382,60 | P35: 229,65
A36: 174 | B36: 092154 | C36: =VLOOKUP(A36,'TABELA SPOLINE'!A:J,10,FALSE) -> #N/A | H36: 415 | I36: 1 | J36: 174-415-1 | K36: =TRIM(A36) -> 174 | L36: PLAF SMART COBRE ONO 3 x E27 95MM 350MM 350MM | M36: 7629 | N36: Spot Line Industria E Comercio | O36: 360,95 | P36: 216,66
A37: 184 | B37: 091986 | C37: =VLOOKUP(A37,'TABELA SPOLINE'!A:J,10,FALSE) -> #N/A | H37: 418 | I37: 2 | J37: 184-418-2 | K37: =TRIM(A37) -> 184 | L37: PLAF SMART BCO 5 x E27 95MM 550MM 550MM | M37: 7629 | N37: Spot Line Industria E Comercio | O37: 734,60 | P37: 440,94
A38: 185 | B38: 091987 | C38: =VLOOKUP(A38,'TABELA SPOLINE'!A:J,10,FALSE) -> #N/A | H38: 418 | I38: 2 | J38: 185-418-2 | K38: =TRIM(A38) -> 185 | L38: PLAF SMART CAFÉ 5 x E27 95MM 550MM 550MM | M38: 7629 | N38: Spot Line Industria E Comercio | O38: 734,60 | P38: 440,94
A39: 186 | B39: 091991 | C39: =VLOOKUP(A39,'TABELA SPOLINE'!A:J,10,FALSE) -> #N/A | H39: 418 | I39: 3 | J39: 186-418-3 | K39: =TRIM(A39) -> 186 | L39: PLAF SMART COBRE POL 5 x E27 95MM 550MM 550MM | M39: 7629 | N39: Spot Line Industria E Comercio | O39: 881,50 | P39: 529,11
A40: 187 | B40: 091992 | C40: =VLOOKUP(A40,'TABELA SPOLINE'!A:J,10,FALSE) -> #N/A | H40: 418 | I40: 3 | J40: 187-418-3 | K40: =TRIM(A40) -> 187 | L40: PLAF SMART DOU POL 5 x E27 95MM 550MM 550MM | M40: 7629 | N40: Spot Line Industria E Comercio | O40: 831,60 | P40: 499,16
...

Sheet Atualizados (551)
A1: SKU | B1: FORNECEDOR | C1: NOME ORIGINAL | D1: PART NUMBER | E1: CONDIÇÃO | F1: CUSTO | G1: MOEDA | H1: CUSTO FINAL? | I1: CUSTO LÍQUIDO | J1: MODIFICADO EM
A2: 092032 | B2: 7629 | E2: DDP | F2: 102.13 | G2: BRL | I2: 93.05 | J2: 45810
A3: 092033 | B3: 7629 | E3: DDP | F3: 102.13 | G3: BRL | I3: 93.05 | J3: 45810
A4: 092034 | B4: 7629 | E4: DDP | F4: 122.55 | G4: BRL | I4: 111.66 | J4: 45810
A5: 092036 | B5: 7629 | E5: DDP | F5: 102.13 | G5: BRL | I5: 93.05 | J5: 45810
A6: 092040 | B6: 7629 | E6: DDP | F6: 167.97 | G6: BRL | I6: 153.04 | J6: 45810
A7: 092041 | B7: 7629 | E7: DDP | F7: 167.97 | G7: BRL | I7: 153.04 | J7: 45810
A8: 092042 | B8: 7629 | E8: DDP | F8: 201.56 | G8: BRL | I8: 183.65 | J8: 45810
A9: 092044 | B9: 7629 | E9: DDP | F9: 167.97 | G9: BRL | I9: 153.04 | J9: 45810
A10: 092048 | B10: 7629 | E10: DDP | F10: 322.49 | G10: BRL | I10: 293.84 | J10: 45810
A11: 092049 | B11: 7629 | E11: DDP | F11: 322.49 | G11: BRL | I11: 293.84 | J11: 45810
A12: 092050 | B12: 7629 | E12: DDP | F12: 386.98 | G12: BRL | I12: 352.6 | J12: 45810
A13: 092052 | B13: 7629 | E13: DDP | F13: 322.49 | G13: BRL | I13: 293.84 | J13: 45810
... A552: 179480 | B552: 7629 | E552: DDP | F552: 278.25 | G552: BRL | I552: 253.53 | J552: 45810

Sheet Não foram atualizados (729)
A1: # Referência | B1: SKU | C1: Nome | D1: Id do Fabricante | E1: Fabricante | F1: Preço | G1: Preço Mínimo
A2: 44 | B2: 177938 | C2: SPOT FLEX PTO TRILHO 2 x E27 300MM | D2: 7629 | E2: Spot Line Industria E Comercio | F2: 519,75 | G2: 311,97
A3: 88 | B3: 092035 | C3: SPOT FLEX BCO / COBRE POL BASE 2 x E27 300MM | D3: 7629 | E3: Spot Line Industria E Comercio | F3: 353,45 | G3: 212,15
A4: 101 | B4: 092043 | C4: SPOT FLEX PTO | D4: 7629 | E4: Spot Line Industria E Comercio | F4: 485,10 | G4: 291,18
A5: 122 | B5: 092131 | C5: SPOT TROIA PTO TRILHO 2 x E27 300MM | D5: 7629 | E5: Spot Line Industria E Comercio | F5: 747,80 | G5: 448,86
A6: 123 | B6: 092132 | C6: SPOT TROIA PTO | D6: 7629 | E6: Spot Line Industria E Comercio | F6: 829,35 | G6: 497,81
A7: 124 | B7: 092133 | C7: SPOT TROIA BCO | D7: 7629 | E7: Spot Line Industria E Comercio | F7: 363,82 | G7: 218,38
A8: 126 | B8: 092134 | C8: SPOT TROIA BCO BRILHANTE | D8: 7629 | E8: Spot Line Industria E Comercio | F8: 917,75 | G8: 550,87
A9: 126 | B9: 092136 | C9: SPOT TROIA PTO TRILHO 3 x E27 500MM | D9: 7629 | E9: Spot Line Industria E Comercio | F9: 1 408,70 | G9: 845,56
A10: 132 | B10: 092141 | C10: PLAF SMART BCO 1 x E27 95MM 250MM 250MM | D10: 7629 | E10: Spot Line Industria E Comercio | F10: 232,62 | G10: 139,63
A11: 133 | B11: 092142 | C11: PLAF SMART CAFÉ 2 x E27 95MM 250MM 250MM | D11: 7629 | E11: Spot Line Industria E Comercio | F11: 232,62 | G11: 139,63
A12: 154 | B12: 177939 | C12: PLAF SMART DOU POL 2 x E27 95MM 250MM 250MM | D12: 7629 | E12: Spot Line Industria E Comercio | F12: 263,35 | G12: 158,07
A13: 166 | B13: 092148 | C13: PLAF SMART PTO 2 x E27 95MM 250MM 250MM | D13: 7629 | E13: Spot Line Industria E Comercio | F13: 232,62 | G13: 139,63
... A719: 6801 | B719: 177827 | C719: 2056 DRIVER 100 WATTS BIVOLT 23CM 48VOLTS 100W IP20 PRETO | D719: 7629 | E719: Spot Line Industria E Comercio | F719: 247,38 | G719: 148,48
B720: 177624 | C720: 1125/3 PERFIL NO FRAME TETTO BRANCO 3 METROS | D720: 7629 | E720: Spot Line Industria E Comercio | F720: 350,30 | G720: 210,26
B721: 177966 | C721: 1167/1 ARANDELA ALT C/ INTERRUPTOR PRETO 1 X MR11 391,5x 33x 439,7MM | D721: 7629 | E721: Spot Line Industria E Comercio | F721: 475,28 | G721: 285,28
B722: 179183 | C722: 1095/1 PENDENTE SET PRETO 3000 K | D722: 7629 | E722: Spot Line Industria E Comercio | F722: 303,05 | G722: 181,90
A723: 1125/3 | B723: 179393 | C723: 1219/1 PENDENTE BELL PRETO 3000K | D723: 7629 | E723: Spot Line Industria E Comercio | F723: 365,28 | G723: 219,25
A724: 1218/40 | B724: 178376 | C724: 1218/40 PENDENTE CLAIRE PRETO 3000K LED BIVOLT 12W 900LM 155,3x400x400MM | D724: 7629 | E724: Spot Line Industria E Comercio | F724: 577,72 | G724: 346,77
A725: 2012/40 | B725: 141787 | C725: 1222/31 ARANDELA CLAIRE BRANCO 3000K LED BIVOLT 5W 375LM 1053X308X443,5MM | D725: 7629 | E725: Spot Line Industria E Comercio | F725: 633,82 | G725: 380,45
A726: 499/1 | B726: 176792 | C726: 1162/15 ARANDELA LUA BRANCO 3000K LED BIVOLT 5W 375LM 47,4x150x150MM | D726: 7629 | E726: Spot Line Industria E Comercio | F726: 289,20 | G726: 173,59
A727: 778/1 | B727: 129335 | C727: CANOPLA SOBREPOR ALDODÃO 20x120x120MM | D727: 7629 | E727: Spot Line Industria E Comercio | F727: 79,58 | G727: 47,76
A728: 820/1 | B728: 129336 | C728: 1156/1 ARANDELA ARK C/ INTERRUPTOR BRANCO 3000K LED BIVOLT 2W 150LM 214,8x33x229MM | D728: 7629 | E728: Spot Line Industria E Comercio | F728: 455,38 | G728: 273,33
A729: 820/1 | B729: 129519 | C729: 1048/1 PENDENTE TORCIA BRANCO CUPULA CRU 1x E27 220x150x120x1500MM | D729: 7629 | E729: Spot Line Industria E Comercio | F729: 232,62 | G729: 139,63

Sheet Precisam ser criados (714)
A1: ID | B1: DESCRIÇÃO | C1: LAMPADA | D1: WATTS | E1: LUMENS | F1: ALTURA | G1: LARGURA | H1: COMPRIMENTO | I1: CABO | J1: PREÇO | K1: OBS.
A2: 348 | B2: 634/1 PENDENTE VERSSAT PRETO | C2: 1 X MR16 | D2: - | E2: - | F2: 500MM | G2: 50MM | H2: 50MM | I2: 1500MM | J2: 76.797
A3: 1300 | B3: 807/4 PENDENTE HONDA DOURADO POLIDO | C3: 4 X MR11 | D3: - | E3: - | F3: 130MM | G3: 50MM | H3: 1320MM | I3: 1200MM | J3: 746.6004
A4: 1304 | B4: 807/4 PENDENTE HONDA PRETO / DOURADO ESCOVADO | C4: 4 X MR11 | D4: - | E4: - | F4: 130MM | G4: 50MM | H4: 1320MM | I4: 1200MM | J4: 622.167
A5: 1314 | B5: 808/5 PENDENTE GRAU DOURADO ESCOVADO | C5: 4 X MR11 - 1 X G9 | D5: - | E5: - | F5: 140MM | G5: 120MM | H5: 1400MM | I5: 1200MM | J5: 824.0652
A6: 1315 | B6: 808/5 PENDENTE GRAU DOURADO ONO | C6: 4 X MR11 - 1 X G9 | D6: - | E6: - | F6: 140MM | G6: 120MM | H6: 1400MM | I6: 1200MM | J6: 686.721
A7: 1316 | B7: 808/5 PENDENTE GRAU DOURADO POLIDO | C7: 4 X MR11 - 1 X G9 | D7: - | E7: - | F7: 140MM | G7: 120MM | H7: 1400MM | I7: 1200MM | J7: 824.0652
A8: 1317 | B8: 808/5 PENDENTE GRAU PRETO | C8: 4 X MR11 - 1 X G9 | D8: - | E8: - | F8: 140MM | G8: 120MM | H8: 1400MM | I8: 1200MM | J8: 686.721
A9: 1318 | B9: 808/5 PENDENTE GRAU PRETO / COBRE ESCOVADO | C9: 4 X MR11 - 1 X G9 | D9: - | E9: - | F9: 140MM | G9: 120MM | H9: 1400MM | I9: 1200MM | J9: 686.721
A10: 1321 | B10: 808/5 PENDENTE GRAU PRETO / DOURADO ESCOVADO | C10: 4 X MR11 - 1 X G9 | D10: - | E10: - | F10: 140MM | G10: 120MM | H10: 1400MM | I10: 1200MM | J10: 686.721
A11: 1322 | B11: 808/5 PENDENTE GRAU PRETO / DOURADO ONO | C11: 4 X MR11 - 1 X G9 | D11: - | E11: - | F11: 140MM | G11: 120MM | H11: 1400MM | I11: 1200MM | J11: 686.721
A12: 1323 | B12: 808/5 PENDENTE GRAU PRETO / DOURADO POLIDO | C12: 4 X MR11 - 1 X G9 | D12: - | E12: - | F12: 140MM | G12: 120MM | H12: 1400MM | I12: 1200MM | J12: 686.721
A13: 1348 | B13: 812/120 PLAFON KIT PRETO3000K | C13: LED BIVOLT | D13: 38WATTS | E13: 2850 | F13: 80MM | G13: 120MM | H13: 1660MM | I13: - | J13: 363.951
A14: 1387 | B14: 817/1 ARANDELA TORCH DOURADO POLIDO CUPULA BRANCA | C14: 1 X E27 | D14: - | E14: - | F14: 500MM | G14: 90MM | H14: 140MM | I14: - | J14: 129.5532
A15: 1408 | B15: 821/1 ARANDELA MADRI BRANCO | C15: 1 X E27 | D15: - | E15: - | F15: 270MM | G15: 160MM | H15: 200MM | I15: - | J15: 150.255
A16: 1521 | B16: 837/1 COLUNA MADRI DOURADO LIXADO | C16: 1 X E27 | D16: - | E16: - | F16: 1550MM | G16: 230MM | H16: 230MM | I16: - | J16: 349.9272
A17: 1990 | B17: 647/1 COLUNA DENVER DOURADO ONO / BRANCO | C17: 1 X E27 | D17: - | E17: - | F17: 1600MM | G17: 210MM | H17: 380MM | I17: - | J17: 173.628
A18: 2151 | B18: 817/1 ARANDELA TORCH DOURADO ONO CUPULA CRU | C18: 1 X E27 | D18: - | E18: - | F18: 500MM | G18: 90MM | H18: 140MM | I18: - | J18: 110.187
A19: 2183 | B19: 817/1 ARANDELA TORCH DOURADO POLIDO CUPULA CRU | C19: 1 X E27 | D19: - | E19: - | F19: 500MM | G19: 90MM | H19: 140MM | I19: - | J19: 129.5532
A20: 2185 | B20: CUPULA TECIDO CRU 80 X 120 X 120 | C20: - | D20: - | E20: - | F20: 120MM | G20: 80MM | H20: 120MM | I20: - | J20: 26.712
A21: 2223 | B21: CUPULA TECIDO BRANCO 80 X 120 X 120 | C21: - | D21: - | E21: - | F21: 120MM | G21: 80MM | H21: 120MM | I21: - | J21: 26.712
A22: 2224 | B22: CUPULA TECIDO PRETO 80 X 120 X 120 | C22: - | D22: - | E22: - | F22: 120MM | G22: 80MM | H22: 120MM | I22: - | J22: 26.712
A23: 2571 | B23: 817/1 ARANDELA TORCH PRETA CUPULA CRU | C23: 1 X E27 | D23: - | E23: - | F23: 500MM | G23: 90MM | H23: 140MM | I23: - | J23: 110.187
A24: 2808 | B24: 817/1 ARANDELA TORCH PRETA / DOURADO ESCOVADO CUPULA CRU | C24: 1 X E27 | D24: - | E24: - | F24: 500MM | G24: 90MM | H24: 140MM | I24: - | J24: 110.187
A25: 2882 | B25: 855/1 SPOT FOCO BASE PRETO | C25: 1 X MR11 | D25: - | E25: - | F25: 110MM | G25: 100MM | H25: 100MM | I25: - | J25: 87.927
A26: 2883 | B26: 855/1 SPOT FOCO BASE DOURADO ESCOVADO | C26: 1 X MR11 | D26: - | E26: - | F26: 110MM | G26: 100MM | H26: 100MM | I26: - | J26: 104.622
A27: 4151 | B27: 896/1 ARANDELA IPE PRETO | C27: 1 X E27 | D27: - | E27: - | F27: 200MM | G27: 150MM | H27: 200MM | I27: - | J27: 107.961 | K27: C/ INTERRUPTOR
A28: 4983 | B28: 844/1 COLUNA STYLE DOURADO ONO 4000K | C28: LED BIVOLT | D28: 22 WATTS | E28: 1650 | F28: 1500MM | G28: 20MM | H28: 175MM | I28: - | J28: 228.165
A29: 5175 | B29: 855/1 SPOT FOCO BASE BRANCO | C29: 1 X MR11 | D29: - | E29: - | F29: 110MM | G29: 100MM | H29: 100MM | I29: - | J29: 87.927
A30: 5177 | B30: 887/1 ARANDELA STRING DOURADO ONO CUPULA CRU | C30: 1 X E27 | D30: - | E30: - | F30: 250MM | G30: 120MM | H30: 170MM | I30: - | J30: 171.402 | K30: C/ INTERRUPTOR
A31: 5234 | B31: 1051/30 PLAFON ELEGANCE PRETO 3000K | C31: LED BIVOLT | D31: 21 WATTS | E31: 1575 | F31: 40MM | G31: 300MM | H31: 300MM | I31: - | J31: 250.425 | K31: SOBREPOR
A32: 5235 | B32: 1051/30 PLAFON ELEGANCE BRANCO 3000K | C32: LED BIVOLT | D32: 21 WATTS | E32: 1575 | F32: 40MM | G32: 300MM | H32: 300MM | I32: - | J32: 250.425 | K32: SOBREPOR
A33: 5236 | B33: 1051/30 PLAFON ELEGANCE DOURADO ONO 3000K | C33: LED BIVOLT | D33: 21 WATTS | E33: 1575 | F33: 40MM | G33: 300MM | H33: 300MM | I33: - | J33: 250.425 | K33: SOBREPOR
A34: 5242 | B34: 1051/50 PLAFON ELEGANCE PRETO 3000K | C34: LED BIVOLT | D34: 32 WATTS | E34: 2240 | F34: 40MM | G34: 500MM | H34: 500MM | I34: - | J34: 366.177 | K34: SOBREPOR
A35: 5244 | B35: 1051/50 PLAFON ELEGANCE DOURADO ONO 3000K | C35: LED BIVOLT | D35: 32 WATTS | E35: 2240 | F35: 40MM | G35: 500MM | H35: 500MM | I35: - | J35: 366.177 | K35: SOBREPOR
A36: 5245 | B36: 1051/50 PLAFON ELEGANCE PRETO E BRANCO 3000K | C36: LED BIVOLT | D36: 32 WATTS | E36: 2240 | F36: 40MM | G36: 500MM | H36: 500MM | I36: - | J36: 366.177 | K36: SOBREPOR
A37: 5258 | B37: 1052/30 PLAFON ELEGANCE PRETO 3000K E DOIS FOCOS | C37: LED BIVOLT | D37: 21 WATTS + 4 WATTS | E37: 1875 | F37: 40MM | G37: 300MM | H37: 300MM | I37: - | J37: 321.657 | K37: SOBREPOR
A38: 5259 | B38: 1052/30 PLAFON ELEGANCE BRANCO 3000K E DOIS FOCOS | C38: LED BIVOLT | D38: 21 WATTS + 4 WATTS | E38: 1875 | F38: 40MM | G38: 300MM | H38: 300MM | I38: - | J38: 321.657 | K38: SOBREPOR
A39: 5261 | B39: 1052/30 PLAFON ELEGANCE DOURADO ONO 3000K E DOIS FOCOS | C39: LED BIVOLT | D39: 21 WATTS + 4 WATTS | E39: 1875 | F39: 40MM | G39: 300MM | H39: 300MM | I39: - | J39: 321.657 | K39: SOBREPOR
A40: 5262 | B40: 1052/30 PLAFON ELEGANCE PRETO E BRANCO 3000K E DOIS FOCOS | C40: LED BIVOLT | D40: 21 WATTS + 4 WATTS | E40: 1875 | F40: 40MM | G40: 300MM | H40: 300MM | I40: - | J40: 321.657 | K40: SOBREPOR
...
